<?xml version="1.0" encoding="utf-8"?>
<!-- This URDF was automatically created by SolidWorks to URDF Exporter! Originally created by Stephen Brawner (brawner@gmail.com) 
     Commit Version: 1.5.1-0-g916b5db  Build Version: 1.5.7152.31018
     For more information, please see http://wiki.ros.org/sw_urdf_exporter -->
<robot name="kr52_description">

  <link name="world"/>

  <joint name="world_to_base" type="fixed">
    <origin xyz="0 0 0" rpy="0 0 0" />
    <parent link="world" />
    <child link="base_link" />
  </joint>

  <link name="base_link">
    <inertial>
	#0.19646 -0.30303 0.18999
      <origin xyz="-0.065069 -0.01427 0.10905" rpy="0 0 0" />
      <mass value="47.205" />
      <inertia ixx="0.5079746" ixy="0.1075298" ixz="0.0244584" iyy="0.9674713" iyz="0.0026404" izz="1.1301033" />
    </inertial>
    <visual>
      <origin xyz="0 0 0" rpy="0 0 0" />
      <geometry>
        <mesh filename="package://kr52_description/meshes/base_link.STL" />
      </geometry>
      <material name="">
        <color rgba="0.4 0.4 0.4 1" />
      </material>
    </visual>
    <collision>
      <origin xyz="0 0 0" rpy="0 0 0" />
      <geometry>
        <mesh filename="package://kr52_description/meshes/base_link.STL" />
      </geometry>
    </collision>
  </link>

  <link name="link_1">
    <inertial>
      <origin xyz="0.0748782 -0.0024585 0.1155281" rpy="0 0 0" />
      <mass value="30.491" />
      <inertia ixx="0.37566" ixy="0.01751" ixz="0.1217" iyy="0.5037" iyz="0.0122" izz="0.5398" />
    </inertial>
    <visual>
      <origin xyz="0 0 0" rpy="0 0 0" />
      <geometry>
        <mesh filename="package://kr52_description/meshes/link_1.STL" />
      </geometry>
      <material name="">
        <color rgba="0.4 0.4 0.4 1" />
      </material>
    </visual>
    <collision>
      <origin xyz="0 0 0" rpy="0 0 0" />
      <geometry>
        <mesh filename="package://kr52_description/meshes/link_1.STL" />
      </geometry>
    </collision>
  </link>

  <joint name="base_to_link1" type="continuous">
    <origin xyz="0 0 0.2255" rpy="0 0 0" />
    <parent link="base_link" />
    <child link="link_1" />
    <axis xyz="0 0 1" />
    <limit
      lower="-2.7053"
      upper="2.7053"
      effort="0"
      velocity="2.72" />
  </joint>

  <link name="link_2">
    <inertial>
      <origin xyz="0.002326 -0.14691 0.3219" rpy="0 0 0" />
      <mass value="19.483" />
      <inertia ixx="1.0010428" ixy="-0.0027968" ixz="-0.0002311" iyy="0.8438332" iyz="0.1673340" izz="0.2118056" />
    </inertial>
    <visual>
      <origin xyz="0 -0.12 0" rpy="0 0 0" />
      <geometry>
        <mesh
          filename="package://kr52_description/meshes/link_2.STL" />
      </geometry>
      <material name="">
        <color rgba="0.4 0.4 0.4 1" />
      </material>
    </visual>
    <collision>
      <origin xyz="0 -0.12 0" rpy="0 0 0" />
      <geometry>
        <mesh
          filename="package://kr52_description/meshes/link_2.STL" />
      </geometry>
    </collision>
  </link>

  <joint name="link1_to_link2" type="continuous">
    <origin xyz="0.18106 -0.002 0.178" rpy="0 0 0" />
    <parent link="link_1" />
    <child link="link_2" />
    <axis xyz="0 1 0" />
    <limit
      lower="-3.1416"
      upper="1.1345"
      effort="0"
      velocity="2.72" />
  </joint>


  <link name="link_3">
    <inertial>
      <origin xyz="0.08651 -0.03078 0.09728" rpy="0 0 0" />
      <mass value="13.345" />
      <inertia ixx="0.18246" ixy="0.03176" ixz="0.05816" iyy="0.18121" iyz="0.03367" izz="0.17365" />
    </inertial>
    <visual>
      <origin xyz="0 -0.135 0" rpy="0 0 0" />
      <geometry>
        <mesh filename="package://kr52_description/meshes/link_3.STL" />
      </geometry>
      <material name="">
        <color rgba="0.79216 0.81961 0.93333 1" />
      </material>
    </visual>
    <collision>
      <origin xyz="0 -0.135 0" rpy="0 0 0" />
      <geometry>
        <mesh filename="package://kr52_description/meshes/link_3.STL" />
      </geometry>
    </collision>
  </link>

  <joint name="link2_to_link3" type="continuous">
    <origin xyz="0 0 0.6" rpy="0 0 0" />
    <parent link="link_2" />
    <child link="link_3" />
    <axis xyz="0 1 0" />
    <limit
      lower="-1.9199"
      upper="2.9671"
      effort="0"
      velocity="3.96" />
  </joint>


  <link name="link_4">
    <inertial>
      <origin xyz="0.17404 -0.00056 0.00022" rpy="0 0 0" />
      <mass value="7.4654" />
      <inertia ixx="0.06612" ixy="-0.00043" ixz="0.00014" iyy="0.094073" iyz="-0.01259" izz="0.15737" />
    </inertial>
    <visual>
      <origin xyz="0 0 0" rpy="0 0 0" />
      <geometry>
        <mesh filename="package://kr52_description/meshes/link_4.STL" />
      </geometry>
      <material name="">
        <color rgba="0.4 0.4 0.4 1" />
      </material>
    </visual>
    <collision>
      <origin xyz="0 0 0" rpy="0 0 0" />
      <geometry>
        <mesh filename="package://kr52_description/meshes/link_4.STL" />
      </geometry>
    </collision>
  </link>

  <joint name="link3_to_link4" type="continuous">
    <origin xyz="0.2246 0 0.17" rpy="0 0 0" />
    <parent link="link_3" />
    <child link="link_4" />
    <axis xyz="1 0 0" />
    <limit
      lower="-2.8798"
      upper="2.8798"
      effort="0"
      velocity="6.81" />
  </joint>


  <link name="link_5">
    <inertial>
      <origin xyz="0.075375 -0.0070921 0" rpy="0 0 0" />
      <mass value="1.9338" />
      <inertia ixx="0.00493" ixy="-0.00058" ixz="0.0" iyy="0.01155" iyz="0.0" izz="0.01465" />
    </inertial>
    <visual>
      <origin xyz="0 0 0" rpy="0 0 0" />
      <geometry>
        <mesh filename="package://kr52_description/meshes/link_5.STL" />
      </geometry>
      <material name="">
        <color rgba="0.4 0.4 0.4 1" />
      </material>
    </visual>
    <collision>
      <origin xyz="0 0 0" rpy="0 0 0" />
      <geometry>
        <mesh
          filename="package://kr52_description/meshes/link_5.STL" />
      </geometry>
    </collision>
  </link>

  <joint
    name="link4_to_link5"
    type="continuous">
    <origin
      xyz="0.3942 0 0"
      rpy="0 0 0" />
    <parent
      link="link_4" />
    <child
      link="link_5" />
    <axis
      xyz="0 1 0" />
    <limit
      lower="-2.4435"
      upper="2.4435"
      effort="0"
      velocity="6.81" />
  </joint>


  <link
    name="link_6">
    <inertial>
      <origin xyz="0 0 0" rpy="0 0 0" />
      <mass value="0.036057" />
      <inertia ixx="0.0000305" ixy="0" ixz="0" iyy="0.0000159" iyz="0" izz="0.0000160" />
    </inertial>
    <visual>
      <origin
        xyz="0 0 0"
        rpy="0 0 0" />
      <geometry>
        <mesh
          filename="package://kr52_description/meshes/link_6.STL" />
      </geometry>
      <material
        name="">
        <color
          rgba="0.4 0.4 0.4 1" />
      </material>
    </visual>
    <collision>
      <origin
        xyz="0 0 0"
        rpy="0 0 0" />
      <geometry>
        <mesh
          filename="package://kr52_description/meshes/link_6.STL" />
      </geometry>
    </collision>
  </link>

  <joint name="link5_to_link6"
    type="continuous">
    <origin
      xyz="0.1845 0.002 0"
      rpy="0 0 0" />
    <parent
      link="link_5" />
    <child
      link="link_6" />
    <axis
      xyz="1 0 0" />
  </joint>


    <!-- ******************** GRIPPER *********************-->
    <link name="base_link_grp">
        <inertial>
            <origin xyz="-0.12444 0.015119 0.11802" rpy="0 0 0" />
            <mass value="0.13435" />
            <inertia ixx="0.0000834" ixy="0.0" ixz="0.0" iyy="0.0001620" iyz="0.0" izz="0.0000794" />
        </inertial>

        <visual>
            <origin xyz="0 0 0" rpy="0 0 0" />
            <geometry>
                <mesh filename="package://gripper_schunk_kuka/meshes/base_link_grp.STL" />
            </geometry>
            <material name="">
                <color rgba="0.79 0.9 0.48 1" />
            </material>
        </visual>
        <collision>
            <origin xyz="0 0 0" rpy="0 0 0" />
            <geometry>
                <mesh filename="package://gripper_schunk_kuka/meshes/base_link_grp.STL" />
            </geometry>
        </collision>
    </link>

    <joint name="link6_to_bgrp" type="fixed">
        <origin xyz="0.0155 0 0" rpy="0 0 0" />
        <parent link="link_6" />
        <child link="base_link_grp" />
    </joint>

    <link name="structure_grp">
        <inertial>
            <origin xyz="-0.00021291 0.023532 3.5559E-05" rpy="0 0 0" />
            <mass value="1.0789" />
            <inertia ixx="0.0009873" ixy="-0.0" ixz="0.0" iyy="0.0015558" iyz="0.0" izz="0.0009789" />
        </inertial>
        <visual>
            <origin xyz="0 0 0" rpy="0 0 0" />
            <geometry>
                <mesh filename="package://gripper_schunk_kuka/meshes/structure_grp.STL" />
            </geometry>
            <material name="">
                <color rgba="0.79 0.9 0.48 1" />
            </material>
        </visual>
        <collision>
            <origin xyz="0 0 0" rpy="0 0 0" />
            <geometry>
                <mesh filename="package://gripper_schunk_kuka/meshes/structure_grp.STL" />
            </geometry>
        </collision>
    </link>

    <joint name="base_to_str_grp" type="fixed">
        <origin xyz="0.0063 0 0" rpy="0 0 0" />
        <parent link="base_link_grp" />
        <child link="structure_grp" />
    </joint>

    <link name="guide_1_grp">
        <inertial>
            <origin xyz="0 0.009 0.027502" rpy="0 0 0" />
            <mass value="0.06552" />
            <inertia ixx="0.0000180" ixy="0.0" ixz="0.0" iyy="0.0000185" iyz="0.0" izz="0.0000046" />
        </inertial>

        <visual>
            <origin xyz="0 0 0" rpy="0 0 0" />
            <geometry>
                <mesh filename="package://gripper_schunk_kuka/meshes/guide_1_grp.STL" />
            </geometry>
            <material name="">
                <color rgba="0 0 0 1" />
            </material>
        </visual>
        <collision>
            <origin xyz="0 0 0" rpy="0 0 0" />
            <geometry>
                <mesh filename="package://gripper_schunk_kuka/meshes/guide_1_grp.STL" />
            </geometry>
        </collision>
    </link>

    <joint name="str_to_g1_grp" type="prismatic">
        <origin xyz="0.0321 0 -0.0043" rpy="3.1416 0 0" />
        <parent link="structure_grp" />
        <child link="guide_1_grp" />
        <axis xyz="0 0 1" />
		<dynamics damping="0.7"/>
        <limit lower="0" upper="0.005" effort="0" velocity="0.05" />
    </joint>

    <link name="guide_2_grp">
        <inertial>
            <origin xyz="0 0.0094 0.027502" rpy="0 0 0" />
            <mass value="0.06552" />
            <inertia ixx="0.0000180" ixy="0.0" ixz="0.0" iyy="0.0000185" iyz="0.0" izz="0.0000046" />
        </inertial>

        <visual>
            <origin xyz="0 0 0" rpy="0 0 0" />
            <geometry>
                <mesh filename="package://gripper_schunk_kuka/meshes/guide_1_grp.STL" />
            </geometry>
            <material name="">
                <color rgba="0 0 0 1" />
            </material>
        </visual>
        <collision>
            <origin xyz="0 0 0" rpy="0 0 0" />
            <geometry>
                <mesh filename="package://gripper_schunk_kuka/meshes/guide_1_grp.STL" />
            </geometry>
        </collision>
    </link>

    <joint name="str_to_g2_grp" type="prismatic">
        #-0.0037239 0.0321 0.00215
        <origin xyz="0.0321 -3.724E-3 2.15E-3" rpy="1.0472 0 0" />
        <parent link="structure_grp" />
        <child link="guide_2_grp" />
        <axis xyz="0 0 1" />
		<dynamics damping="0.7"/>
        <limit lower="0" upper="0.005" effort="0" velocity="0.05" />
    </joint>

    <link name="guide_3_grp">
        <inertial>
            <origin xyz="0 0.0094502 0.025291" rpy="0 0 0" />
            <mass value="0.06552" />
            <inertia ixx="0.0000180" ixy="0.0" ixz="0.0" iyy="0.0000185" iyz="0.0" izz="0.0000046" />
        </inertial>

        <visual>
            <origin xyz="0 0 0" rpy="0 0 0" />
            <geometry>
                <mesh filename="package://gripper_schunk_kuka/meshes/guide_1_grp.STL" />
            </geometry>
            <material name="">
                <color rgba="0 0 0 1" />
            </material>
        </visual>
        <collision>
            <origin xyz="0 0 0" rpy="0 0 0" />
            <geometry>
                <mesh filename="package://gripper_schunk_kuka/meshes/guide_1_grp.STL" />
            </geometry>
        </collision>
    </link>

    <joint name="str_to_g3_grp" type="prismatic">
        #-0.0037239 0.0321 0.00215
        <origin xyz="0.0321 3.724E-3 2.15E-3" rpy="5.236 0 0" />
        <parent link="structure_grp" />
        <child link="guide_3_grp" />
        <axis xyz="0 0 1" />
		<dynamics damping="0.7"/>
        <limit lower="0" upper="0.005" effort="0" velocity="0.05" />
    </joint>

    <link name="finger1_grp">
        <inertial>
            <origin xyz="0.0099787 0.037092 0.006" rpy="0 0 0" />
            <mass value="0.091368" />
            <inertia ixx="0.0000410" ixy="-0.0000150" ixz="0.0" iyy="0.000018" iyz="0.0" izz="0.0000576" />
        </inertial>

        <visual>
            <origin xyz="0 0 0" rpy="0 0 0" />
            <geometry>
                <mesh filename="package://gripper_schunk_kuka/meshes/finger1_grp.STL" />
            </geometry>
            <material name="">
                <color rgba="0.75294 1 1 1" />
            </material>
        </visual>
        <collision>
            <origin xyz="0 0 0" rpy="0 0 0" />
            <geometry>
                <mesh filename="package://gripper_schunk_kuka/meshes/finger1_grp.STL" />
            </geometry>
        </collision>
    </link>

    <joint name="g1_to_f1_grp" type="fixed">
        #0.006 0.0209 0.0165
        <origin xyz="0.0209 -0.0053 0.0165" rpy="0 1.5708 0" />
        <parent link="guide_1_grp" />
        <child link="finger1_grp" />
    </joint>

    <link name="finger2_grp">
        <inertial>
            <origin xyz="0.0099787 0.037092 0.006" rpy="0 0 0" />
            <mass value="0.091368" />
            <inertia ixx="0.0000410" ixy="-0.0000150" ixz="0.0" iyy="0.000018" iyz="0.0" izz="0.0000576" />
        </inertial>

        <visual>
            <origin xyz="0 0 0" rpy="0 0 0" />
            <geometry>
                <mesh filename="package://gripper_schunk_kuka/meshes/finger1_grp.STL" />
            </geometry>
            <material name="">
                <color rgba="0.75294 1 1 1" />
            </material>
        </visual>
        <collision>
            <origin xyz="0 0 0" rpy="0 0 0" />
            <geometry>
                <mesh filename="package://gripper_schunk_kuka/meshes/finger1_grp.STL" />
            </geometry>
        </collision>
    </link>

    <joint name="g2_to_f2_grp" type="fixed">
        <origin xyz="0.0209 -0.0053 0.0165" rpy="0 1.5708 0" />
        <parent link="guide_2_grp" />
        <child link="finger2_grp" />
    </joint>

    <link name="finger3_grp">
        <inertial>
            <origin xyz="0.0099787 0.037092 0.006" rpy="0 0 0" />
            <mass value="0.091368" />
            <inertia ixx="0.0000410" ixy="-0.0000150" ixz="0.0" iyy="0.000018" iyz="0.0" izz="0.0000576" />
        </inertial>

        <visual>
            <origin xyz="0 0 0" rpy="0 0 0" />
            <geometry>
                <mesh filename="package://gripper_schunk_kuka/meshes/finger1_grp.STL" />
            </geometry>
            <material name="">
                <color rgba="0.75294 1 1 1" />
            </material>
        </visual>
        <collision>
            <origin xyz="0 0 0" rpy="0 0 0" />
            <geometry>
                <mesh filename="package://gripper_schunk_kuka/meshes/finger1_grp.STL" />
            </geometry>
        </collision>
    </link>
    <joint name="g3_to_f3_grp" type="fixed">
        <origin xyz="0.0209 -0.0053 0.0165" rpy="0 1.5708 0" />
        <parent link="guide_3_grp" />
        <child link="finger3_grp" />
    </joint>

<!-- *********************** TRANSMITIONS ************************* -->

    <transmission name="trans_base_to_link1">
        <type>transmission_interface/SimpleTransmission</type>
        <joint name="base_to_link1">
            <hardwareInterface>hardware_interface/PositionJointInterface</hardwareInterface>
        </joint>
        <actuator name="base_to_link1_motor">
            <hardwareInterface>hardware_interface/PositionJointInterface</hardwareInterface>
            <mechanicalReduction>1</mechanicalReduction>
        </actuator>
    </transmission>
    <transmission name="trans_link1_to_link2">
        <type>transmission_interface/SimpleTransmission</type>
        <joint name="link1_to_link2">
            <hardwareInterface>hardware_interface/PositionJointInterface</hardwareInterface>
        </joint>
        <actuator name="link1_to_link2_motor">
            <hardwareInterface>hardware_interface/PositionJointInterface</hardwareInterface>
            <mechanicalReduction>1</mechanicalReduction>
        </actuator>
    </transmission>
    <transmission name="trans_link2_to_link3">
        <type>transmission_interface/SimpleTransmission</type>
        <joint name="link2_to_link3">
            <hardwareInterface>hardware_interface/PositionJointInterface</hardwareInterface>
        </joint>
        <actuator name="link2_to_link3_motor">
            <hardwareInterface>hardware_interface/PositionJointInterface</hardwareInterface>
            <mechanicalReduction>1</mechanicalReduction>
        </actuator>
    </transmission>
    <transmission name="trans_link3_to_link4">
        <type>transmission_interface/SimpleTransmission</type>
        <joint name="link3_to_link4">
            <hardwareInterface>hardware_interface/PositionJointInterface</hardwareInterface>
        </joint>
        <actuator name="link3_to_link4_motor">
            <hardwareInterface>hardware_interface/PositionJointInterface</hardwareInterface>
            <mechanicalReduction>1</mechanicalReduction>
        </actuator>
    </transmission>
    <transmission name="trans_link4_to_link5">
        <type>transmission_interface/SimpleTransmission</type>
        <joint name="link4_to_link5">
            <hardwareInterface>hardware_interface/PositionJointInterface</hardwareInterface>
        </joint>
        <actuator name="link4_to_link5_motor">
            <hardwareInterface>hardware_interface/PositionJointInterface</hardwareInterface>
            <mechanicalReduction>1</mechanicalReduction>
        </actuator>
    </transmission>
    <transmission name="trans_link5_to_link6">
        <type>transmission_interface/SimpleTransmission</type>
        <joint name="link5_to_link6">
            <hardwareInterface>hardware_interface/PositionJointInterface</hardwareInterface>
        </joint>
        <actuator name="link5_to_link6_motor">
            <hardwareInterface>hardware_interface/PositionJointInterface</hardwareInterface>
            <mechanicalReduction>1</mechanicalReduction>
        </actuator>
    </transmission>
    <transmission name="trans_str_to_g1_grp">
        <type>transmission_interface/SimpleTransmission</type>
        <joint name="str_to_g1_grp">
            <hardwareInterface>hardware_interface/EffortJointInterface</hardwareInterface>
        </joint>
        <actuator name="str_to_g1_grp_motor">
            <hardwareInterface>hardware_interface/EffortJointInterface</hardwareInterface>
            <mechanicalReduction>1</mechanicalReduction>
        </actuator>
    </transmission>
    <transmission name="trans_str_to_g2_grp">
        <type>transmission_interface/SimpleTransmission</type>
        <joint name="str_to_g2_grp">
            <hardwareInterface>hardware_interface/EffortJointInterface</hardwareInterface>
        </joint>
        <actuator name="str_to_g2_grp_motor">
            <hardwareInterface>hardware_interface/EffortJointInterface</hardwareInterface>
            <mechanicalReduction>1</mechanicalReduction>
        </actuator>
    </transmission>
    <transmission name="trans_str_to_g3_grp">
        <type>transmission_interface/SimpleTransmission</type>
        <joint name="str_to_g3_grp">
            <hardwareInterface>hardware_interface/EffortJointInterface</hardwareInterface>
        </joint>
        <actuator name="str_to_g3_grp_motor">
            <hardwareInterface>hardware_interface/EffortJointInterface</hardwareInterface>
            <mechanicalReduction>1</mechanicalReduction>
        </actuator>
    </transmission>

    <!-- ***************** Gazebo plugin for ROS Control ********************** -->
    <gazebo>
        <plugin name="gazebo_ros_control" filename="libgazebo_ros_control.so">
            <robotNamespace>/</robotNamespace>
        </plugin>
    </gazebo>

</robot>
